Workbook

Sheet Read Me
A1: IPC Digital Platform — Estimate v2
A2: Rebuilt 18 Aug 2026 against verified evidence from the live IPC estate. Supersedes v1.
B4: WHAT CHANGED IN v2
B5: 1. Verified, not assumed | C5: v1 assumed ~2,500 pages of migration and a greenfield build. Both were wrong. The live estate was inspected and the baselines below are counted, not estimated.
B6: 2. Probabilistic, not point | C6: v1 gave a single number plus a 12% contingency I chose. v2 derives P50 / P80 / P90 from the three-point spread already in the model, and derives contingency from an expected-value risk register.
B7: 3. Build-vs-adopt tested | C7: v1 priced three flavours of bespoke build. v2 adds Scenario D, which tests replatforming the existing estate against a full rebuild.
B8: 4. Unit economics | C8: v2 computes cost per transaction against the real catalogue and order volumes, which is the first number an evaluation committee will calculate.
B9: 5. Price, not just cost | C9: v2 adds margin, GST, milestone billing, cash-flow curve, performance guarantee and liquidated-damages exposure.
B10: 6. Triangulated | C10: v2 cross-checks the bottom-up build against a top-down analogy and a capability-count method. Where they disagree, that gap is stated rather than hidden.
B12: VERIFIED BASELINES | C12: All figures below were read from the live IPC estate on 18 Aug 2026.
B13: Current CMS | C13: Joomla. Confirmed from the meta-generator on every page. Migration is Joomla-to-target, not greenfield.
B14: Current commerce | C14: OpenCart, live at /shop/. Confirmed from URL routing (index.php?route=product/category). Doc B's e-commerce module is a REPLATFORM with existing product, customer and order data — scope absent from Doc B entirely.
B15: IPRS catalogue | C15: 702 reference substances. Counted from List-of-IP-Reference-Substances.pdf, last updated 24/06/2026. Each row carries current lot, one previous lot with validity, and quantity per vial.
B16: IMPRS catalogue | C16: 639 reference impurities. Counted from Impuritie_List.pdf, last updated 24/06/2026. Each row carries API/monograph linkage, lot data, quantity and TWO price tiers.
B17: Total priced SKUs | C17: 1,341 plus publications, subscriptions, phytochemical and botanical standards, and the Prednisone calibrator tablet.
... B24: Estate hygiene | C24: Production pages link to a vendor staging host (ipc.maxtraserver.in); a G20 banner from 2023 is still live; the site map's own last-updated date is July 2019; the NFI section still headlines 2021 while NFI 2026 is being procured. This is direct evidence for Doc B's archival and lifecycle requirements.
B26: VERIFIED COMPLIANCE POSITION
B27: GIGW 3.0 | C27: 88 mandatory guidelines across quality, accessibility, cybersecurity and lifecycle management. Conforms to WCAG 2.1 Level AA with 17 added success criteria. Its cybersecurity chapter was written by CERT-In and EXPLICITLY covers mobile apps — so Doc A omitting GIGW is a compliance gap, not merely an inconsistency with Doc B.
B28: STQC | C28: Conformity is evidenced by Certified Quality Website (CQW) certification from the STQC Directorate, involving document review plus frontend and backend testing.
B29: DPDP | C29: Both documents cite the 'DPDP Bill, 2023'. It has been an Act since August 2023, and the DPDP Rules were notified on 13 November 2025. Compliance is phased: the Board and definitions took effect immediately, penalties and Consent Manager registration from 13 November 2026, and FULL COMPLIANCE IS DUE 13 MAY 2027. A 16-month programme starting now lands on or after that date — DPDP is a hard delivery constraint, not a design preference.
B30: Correction to v1 | C30: v1 argued Google Analytics conflicts with DPDP on localisation grounds. That was wrong: the final Rules use a blacklist model for cross-border transfer, not data localisation. The real constraints are consent, purpose limitation, retention limits and a 90-day grievance timeline.
B32: HOW TO USE | C32: Blue = input, change these. Black = formula. Green = cross-sheet link. Yellow = primary lever.
B33: Row shading | C33: Pink = scope the documents omit but the outcome requires. Green = scope newly identified from inspecting the live estate, absent from both documents.
B34: Excluded | C34: IPC staff time; content authoring; payment gateway TDR; statutory fees; physical cold-chain infrastructure; IPC-side hardware.
B36: WHAT CHANGED IN v5
B37: One sheet, both scenarios | C37: This workbook now prices two different questions in one place: what it costs to build Lotmark as a product, and what IPC costs under five routes including adopting that product.
B38: Product Build sheet | C38: New. The product had never been estimated — only customer deployments had. Same three-point and Monte Carlo method.
B39: Scenario E | C39: New. Every IPC module carries a factor for what survives once the product supplies the core, modelled per module rather than as a global multiplier.
B40: Why it matters | C40: Scenarios A to D all assume a bespoke build. If the product exists, none of them is the cheapest route for IPC, and the workbook previously could not say so.
B42: UNITS AND CONVENTIONS
B43: PD — person-day | C43: One person working one day. 21 person-days make one person-month. All effort figures in this workbook are person-days unless a column header says otherwise.
B44: INR crore (Cr) | C44: Ten million rupees. Used for build cost, total cost of ownership and quoted price.
B45: INR lakh | C45: One hundred thousand rupees. Used for pass-through and licence lines. Note that crore and lakh both appear in this workbook — always read the column header.
B46: INR / PD | C46: The blended rate: rupees per person-day. Multiply effort by this to get cost.
B47: Factor (0–1) | C47: Dimensionless. The fraction of a module that survives under a given scenario. 1.00 means untouched; 0.15 means 15% of the original effort remains.
B48: Probability (0–1) | C48: Dimensionless likelihood of a risk event, used to weight its impact.
B49: P50 / P80 / P90 | C49: Confidence levels from the Monte Carlo, expressed in person-days. P80 means four runs in five finish at or below that figure.
B50: Sigma | C50: Standard deviation of a module's three-point spread, in person-days.
B51: FP / KSLOC | C51: Function points and thousands of source lines of code, used only on the Independent Estimate sheet.
B52: Months | C52: Schedule durations on the Timeline sheet. Columns M1 to M16 are programme months, not calendar months.
...

Sheet Build & Verification
A1: Build and Verification
A2: Three deliverables, one toolchain. The toolchain is carried inside the product and exportable from its Build screen.
B4: THE THREE DELIVERABLES
A5: Ref | B5: Outcome | C5: File | D5: What it is
A6: D1 | B6: Product | C6: lotmark-app.html | D6: The working application. Nine roles, 22 console modules, ISO 17034 and 21 CFR Part 11 controls that can be exercised rather than read. Carries build.py inside it, exportable from Build and verification.
A7: D2 | B7: Wireframe | C7: lotmark-product-wireframe.html | D7: 37 screens of product design, including the market and deployment decision screens. Its screen list is the source the product's coverage map is generated from.
A8: D3 | B8: Estimation | C8: Lotmark_and_IPC_Estimate_v5.xlsx | D8: This workbook. Cost and revenue for both the product build and five IPC routes, in one place.
B10: SHIP SEQUENCE — run in this order after any change
A11: Step | B11: Command | C11: Guards | D11: Why it is in this position
A12: 1 | B12: recalc the workbook | C12: cached values must exist | D12: openpyxl drops cached values on save; every reference check would otherwise report a false failure
A13: 2 | B13: python3 build.py sync | C13: asserts substitution size and key symbols; refuses to write a damaged file | D13: regenerates the coverage map from the wireframe and injects figures, so drift cannot survive a build
A14: 3 | B14: python3 build.py check | C14: 23 checks; exits non-zero | D14: catches duplicate declarations, broken references, undefined permissions, coverage drift
A15: 4 | B15: open the product, Build and verification | C15: 16 runtime invariants | D15: only evaluable with data loaded — signatures, chain, referential integrity
A16: 5 | B16: the five JS harnesses | C16: 166 assertions, each asserting its own count | D16: behaviour, not structure
B18: WHAT THE TOOLCHAIN CHECKS, AND THE DEFECT THAT PUT IT THERE
A19: Ref | B19: Check | C19: Where it runs | D19: The defect it exists because of
A20: V1 | B20: Duplicate function and constant declarations | C20: build.py check | D20: A re-run patch script inserted a block twice, nested inside the first. JavaScript accepts it silently.
A21: V2 | B21: Cross-sheet references land on numeric cells | C21: build.py check | D21: A hardcoded coordinate pointed at a paragraph of prose after rows shifted.
A22: V3 | B22: Named ranges resolve to numbers | C22: build.py check | D22: Same root cause: coordinates as an addressing scheme.
A23: V4 | B23: No cached formula errors | C23: build.py check | D23: A row insert broke an entire block, because openpyxl does not translate formulas.
A24: V5 | B24: Every permission used is defined and granted | C24: build.py check + product | D24: An export guarded on a permission absent from the model, so it refused everyone silently.
A25: V6 | B25: Every module has a renderer | C25: build.py check + product | D25: A dead fallback key crashed the app for a role with no console modules.
A26: V7 | B26: Inline handlers call functions that exist | C26: build.py check | D26: Handlers are strings; a rename does not break them until someone clicks.
A27: V8 | B27: No backticks or mangled escapes in handlers | C27: build.py check | D27: A nested backtick and a Python-mangled apostrophe each terminated a template literal.
A28: V9 | B28: Coverage map matches the wireframe | C28: build.py check | D28: The artefact that verifies the product drifted from the product.
A29: V10 | B29: Harnesses assert their own assertion count | C29: build.py check | D29: Three separate green results came from tests that never ran.
A30: V11 | B30: Signatures carry a valid competence basis | C30: product runtime | D30: Nine seeded signatures had none, found by the product checking itself.
... A32: V13 | B32: Referential integrity across orders, lots, vault, studies | C32: product runtime | D32: Only evaluable with data loaded.
B34: Standing caveat | C34: The toolchain protects these three files from the people editing them. It does not test whether a reference material producer would buy the product. The addressable share in the Market and Revenue sheet is invented, and it moves the answer more than any other input here.

Sheet Toolchain (build.py)
A1: build.py — the complete toolchain
A2: Copy column B to a file named build.py, then run: python3 build.py all. Column A is the line number only. Lines beginning with an equals sign are stored as forced text so the spreadsheet does not read them as formulas.
A4: 1 | B4: #!/usr/bin/env python3
A5: 2 | B5: """
A6: 3 | B6: build.py — the entire Lotmark toolchain in one file.
A7: 4
A8: 5 | B8: python3 build.py sync regenerate the coverage map and inject workbook figures
A9: 6 | B9: python3 build.py check run 23 preflight checks across all three artefacts
A10: 7 | B10: python3 build.py all sync, then check (the ship sequence)
A11: 8
A12: 9 | B12: Also importable as a library for `Patcher` and `cell_by_label`.
A13: 10
A14: 11 | B14: Every check here exists because the corresponding defect actually happened during this
A15: 12 | B15: build. Discipline did not catch them; a script would have. Recalculate the workbook
A16: 13 | B16: before running — openpyxl drops cached values on save.
A17: 14 | B17: """
A18: 15 | B18: import openpyxl, re, sys, os, json
A19: 16 | B19: from openpyxl.workbook.defined_name import DefinedName
A20: 17 | B20: from openpyxl.utils import quote_sheetname, absolute_coordinate
A21: 18
A22: 19 | B22: XL = "/mnt/user-data/outputs/Lotmark_and_IPC_Estimate_v5.xlsx"
A23: 20 | B23: WF = "/mnt/user-data/outputs/lotmark-product-wireframe.html"
A24: 21 | B24: AP = "/mnt/user-data/outputs/lotmark-app.html"
A25: 22
A26: 23
A27: 24 | B27: # A file that carries this script inside it must not be analysed WITH this script inside
A28: 25 | B28: # it: every literal here (const PERMS={, const COVERAGE=[, guard('...')) would be read as
A29: 26 | B29: # application code. sync() found its own embedded copy and patched the wrong place.
A30: 27 | B30: # Strip the carrier before reading, and never write inside it.
A31: 28 | B31: EMBED_OPEN = '<script type="text/plain" id="build-src">'
A32: 29 | B32: EMBED_CLOSE = '</script>'
A33: 30
A34: 31 | B34: def strip_embedded(src):
A35: 32 | B35: i = src.find(EMBED_OPEN)
A36: 33 | B36: if i == -1:
A37: 34 | B37: return src
A38: 35 | B38: j = src.find(EMBED_CLOSE, i)
A39: 36 | B39: return src[:i] + src[j + len(EMBED_CLOSE):]
A40: 37
A41: 38 | B41: def split_embedded(src):
...

Sheet Product Build
A1: Lotmark — Cost to Build the Product
A2: Never estimated before. This is the product itself, not any one customer's deployment. Same three-point and Monte Carlo method as the rest of the workbook.
A4: Ref | B4: Module | C4: Opt (PD) | D4: Likely (PD) | E4: Pess (PD) | F4: Expected (PD) | G4: Sigma (PD) | H4: Note
B5: Foundation
A6: A1 | B6: Discovery, domain model and architecture | C6: 24 | D6: 36 | E6: 55 | F6: =ROUND((C6+4*D6+E6)/6,0) -> 37 | G6: =ROUND((E6-C6)/6,1) -> 5.2 | H6: The three traceability closures are architecture, not features.
A7: A2 | B7: Design system and UX across ~40 screens | C7: 30 | D7: 45 | E7: 68 | F7: =ROUND((C7+4*D7+E7)/6,0) -> 46 | G7: =ROUND((E7-C7)/6,1) -> 6.3
B8: Foundation subtotal | C8: =SUM(C6:C7) -> 54 | D8: =SUM(D6:D7) -> 81 | E8: =SUM(E6:E7) -> 123 | F8: =SUM(F6:F7) -> 83
B9: Production
A10: P1 | B10: Project and production plan | C10: 20 | D10: 30 | E10: 46 | F10: =ROUND((C10+4*D10+E10)/6,0) -> 31 | G10: =ROUND((E10-C10)/6,1) -> 4.3 | H10: ISO 17034 §7.2
A11: P2 | B11: Candidate material, processing steps, packaging | C11: 16 | D11: 24 | E11: 38 | F11: =ROUND((C11+4*D11+E11)/6,0) -> 25 | G11: =ROUND((E11-C11)/6,1) -> 3.7 | H11: §7.4
A12: P3 | B12: Homogeneity study and statistics | C12: 22 | D12: 34 | E12: 52 | F12: =ROUND((C12+4*D12+E12)/6,0) -> 35 | G12: =ROUND((E12-C12)/6,1) -> 5 | H12: §7.5 — produces u(bb)
A13: P4 | B13: Stability studies, short, long and ongoing | C13: 24 | D13: 36 | E13: 55 | F13: =ROUND((C13+4*D13+E13)/6,0) -> 37 | G13: =ROUND((E13-C13)/6,1) -> 5.2 | H13: §7.6 — produces shelf life and transport class
A14: P5 | B14: Characterisation and interlaboratory comparison | C14: 20 | D14: 30 | E14: 48 | F14: =ROUND((C14+4*D14+E14)/6,0) -> 31 | G14: =ROUND((E14-C14)/6,1) -> 4.7 | H14: §7.7 — produces u(char)
A15: P6 | B15: Property values and uncertainty budget engine | C15: 26 | D15: 38 | E15: 58 | F15: =ROUND((C15+4*D15+E15)/6,0) -> 39 | G15: =ROUND((E15-C15)/6,1) -> 5.3 | H15: §7.8 — derived, never typed
A16: P7 | B16: Value authorisation workflow | C16: 14 | D16: 22 | E16: 34 | F16: =ROUND((C16+4*D16+E16)/6,0) -> 23 | G16: =ROUND((E16-C16)/6,1) -> 3.3 | H16: §6.2 — non-subcontractable, SoD enforced
A17: P8 | B17: Lot register, supersession and expiry | C17: 20 | D17: 30 | E17: 46 | F17: =ROUND((C17+4*D17+E17)/6,0) -> 31 | G17: =ROUND((E17-C17)/6,1) -> 4.3 | H17: §7.9
B18: Production subtotal | C18: =SUM(C10:C17) -> 162 | D18: =SUM(D10:D17) -> 244 | E18: =SUM(E10:E17) -> 377 | F18: =SUM(F10:F17) -> 252
B19: Certification
A20: C1 | B20: Certificate generation from authorised values | C20: 22 | D20: 32 | E20: 50 | F20: =ROUND((C20+4*D20+E20)/6,0) -> 33 | G20: =ROUND((E20-C20)/6,1) -> 4.7 | H20: ISO Guide 31
A21: C2 | B21: Template designer and versioning | C21: 26 | D21: 38 | E21: 58 | F21: =ROUND((C21+4*D21+E21)/6,0) -> 39 | G21: =ROUND((E21-C21)/6,1) -> 5.3 | H21: The multi-tenant hinge
A22: C3 | B22: Registry, reissue, diff and holder list | C22: 20 | D22: 30 | E22: 46 | F22: =ROUND((C22+4*D22+E22)/6,0) -> 31 | G22: =ROUND((E22-C22)/6,1) -> 4.3 | H22: Closure 2
B23: Certification subtotal | C23: =SUM(C20:C22) -> 68 | D23: =SUM(D20:D22) -> 100 | E23: =SUM(E20:E22) -> 154 | F23: =SUM(F20:F22) -> 103
B24: Distribution
A25: D1 | B25: Catalogue and listing rules | C25: 14 | D25: 22 | E25: 34 | F25: =ROUND((C25+4*D25+E25)/6,0) -> 23 | G25: =ROUND((E25-C25)/6,1) -> 3.3
A26: D2 | B26: Entitlement engine and verification workflow | C26: 18 | D26: 26 | E26: 40 | F26: =ROUND((C26+4*D26+E26)/6,0) -> 27 | G26: =ROUND((E26-C26)/6,1) -> 3.7
A27: D3 | B27: Orders and lot allocation | C27: 20 | D27: 30 | E27: 46 | F27: =ROUND((C27+4*D27+E27)/6,0) -> 31 | G27: =ROUND((E27-C27)/6,1) -> 4.3 | H27: Allocation at the line makes the holder list computable
A28: D4 | B28: Dispatch and cold chain | C28: 22 | D28: 32 | E28: 50 | F28: =ROUND((C28+4*D28+E28)/6,0) -> 33 | G28: =ROUND((E28-C28)/6,1) -> 4.7 | H28: §7.10
A29: D5 | B29: Customer accounts and laboratory vault | C29: 24 | D29: 36 | E29: 55 | F29: =ROUND((C29+4*D29+E29)/6,0) -> 37 | G29: =ROUND((E29-C29)/6,1) -> 5.2 | H29: The second product, built as a surface on the first
A30: D6 | B30: Public certificate retrieval API | C30: 12 | D30: 18 | E30: 28 | F30: =ROUND((C30+4*D30+E30)/6,0) -> 19 | G30: =ROUND((E30-C30)/6,1) -> 2.7 | H30: Distribution strategy, not a feature
B31: Distribution subtotal | C31: =SUM(C25:C30) -> 110 | D31: =SUM(D25:D30) -> 164 | E31: =SUM(E25:E30) -> 253 | F31: =SUM(F25:F30) -> 170
B32: Compliance
A33: Q1 | B33: ISO 17034 conformance engine and clause map | C33: 24 | D33: 36 | E33: 55 | F33: =ROUND((C33+4*D33+E33)/6,0) -> 37 | G33: =ROUND((E33-C33)/6,1) -> 5.2 | H33: The reason a producer buys
A34: Q2 | B34: Audit ledger, hash chain, verify and export | C34: 16 | D34: 24 | E34: 38 | F34: =ROUND((C34+4*D34+E34)/6,0) -> 25 | G34: =ROUND((E34-C34)/6,1) -> 3.7 | H34: §8.4
A35: Q3 | B35: Equipment, calibration and impact query | C35: 16 | D35: 24 | E35: 38 | F35: =ROUND((C35+4*D35+E35)/6,0) -> 25 | G35: =ROUND((E35-C35)/6,1) -> 3.7 | H35: Closure 1
A36: Q4 | B36: Competence register, dated, enforced at signing | C36: 14 | D36: 20 | E36: 32 | F36: =ROUND((C36+4*D36+E36)/6,0) -> 21 | G36: =ROUND((E36-C36)/6,1) -> 3 | H36: Closure 3 — §6.3
A37: Q5 | B37: Subcontractor register with forbidden-activity block | C37: 10 | D37: 15 | E37: 24 | F37: =ROUND((C37+4*D37+E37)/6,0) -> 16 | G37: =ROUND((E37-C37)/6,1) -> 2.3 | H37: §6.2
A38: Q6 | B38: Complaints, nonconformity and CAPA | C38: 18 | D38: 26 | E38: 40 | F38: =ROUND((C38+4*D38+E38)/6,0) -> 27 | G38: =ROUND((E38-C38)/6,1) -> 3.7 | H38: §8.6, §8.7
B39: Compliance subtotal | C39: =SUM(C33:C38) -> 98 | D39: =SUM(D33:D38) -> 145 | E39: =SUM(E33:E38) -> 227 | F39: =SUM(F33:F38) -> 151
B40: Platform
A41: X1 | B41: Multi-tenancy, isolation and data residency | C41: 30 | D41: 45 | E41: 70 | F41: =ROUND((C41+4*D41+E41)/6,0) -> 47 | G41: =ROUND((E41-C41)/6,1) -> 6.7 | H41: Government producers require in-country hosting
...

Sheet Market & Revenue
A1: Market and Revenue Model
A2: Moved here from the wireframe. The cost side and the revenue side of the same decision now live in one file.
B4: COUNTED POPULATIONS — not estimated
A5: Ref | B5: Population | C5: Count | D5: Source | E5: Confidence | F5: Note
A6: M1 | B6: RM producers accredited under the ILAC MRA | C6: 320 | D6: ILAC Secretariat 2025 | E6: authoritative | F6: The producer TAM. Every prospect can be named.
A7: M2 | B7: Producers registered in COMAR | C7: 220 | D7: BAM COMAR guide | E7: floor | F7: Voluntary listing, so an undercount.
A8: M3 | B8: Certified reference materials listed in COMAR | C8: 11000 | D8: BAM COMAR guide | E8: floor | F8: About 50 per producer; the estate examined carries 1,341.
A9: M4 | B9: Laboratories accredited to ISO/IEC 17025 | C9: 114600 | D9: ILAC Secretariat 2025 | E9: authoritative | F9: The vault TAM, 358x the producer population.
B11: MODEL A — THE PRODUCER PLATFORM
A12: Ref | B12: Step | C12: Low | D12: Base | E12: High | F12: Basis
A13: A1 | B13: Producer universe | C13: 400 | D13: 550 | E13: 700 | F13: M1 accredited plus unaccredited producers
A14: A2 | B14: Addressable share (carry enough SKUs to need a system) | C14: 0.3 | D14: 0.35 | E14: 0.4 | F14: WEAKEST INPUT. Nobody publishes SKU counts per producer.
A15: A3 | B15: Addressable producers | C15: =ROUND(C13*C14,0) -> 120 | D15: =ROUND(D13*D14,0) -> 193 | E15: =ROUND(E13*E14,0) -> 280
A16: A4 | B16: Five-year penetration | C16: 0.15 | D16: 0.25 | E16: 0.4 | F16: Vertical SaaS into a listable population
A17: A5 | B17: Customers | C17: =ROUND(C15*C16,0) -> 18 | D17: =ROUND(D15*D16,0) -> 48 | E17: =ROUND(E15*E16,0) -> 112
A18: A6 | B18: Annual contract value (INR lakh) | C18: 25 | D18: 50 | E18: 92 | F18: Benchmarked against mid-market LIMS
A19: A7 | B19: Annual recurring revenue (INR Cr) | C19: =C17*C18/100 -> 4.5 | D19: =D17*D18/100 -> 24 | E19: =E17*E18/100 -> 103.04
B21: MODEL B — THE LABORATORY VAULT
A22: Ref | B22: Step | C22: Low | D22: Base | E22: High | F22: Basis
A23: B1 | B23: Accredited laboratory universe | C23: 114600 | D23: 114600 | E23: 114600 | F23: M4, an authoritative count
A24: B2 | B24: Addressable share (hold enough standards to care) | C24: 0.3 | D24: 0.4 | E24: 0.5 | F24: WEAKEST INPUT. Untested.
A25: B3 | B25: Addressable laboratories | C25: =ROUND(C23*C24,0) -> 34380 | D25: =ROUND(D23*D24,0) -> 45840 | E25: =ROUND(E23*E24,0) -> 57300
A26: B4 | B26: Five-year penetration | C26: 0.005 | D26: 0.02 | E26: 0.05 | F26: Self-serve, low touch, seeded by producers
A27: B5 | B27: Customers | C27: =ROUND(C25*C26,0) -> 172 | D27: =ROUND(D25*D26,0) -> 917 | E27: =ROUND(E25*E26,0) -> 2865
A28: B6 | B28: Annual contract value (INR lakh) | C28: 1 | D28: 2.5 | E28: 5 | F28: Per-laboratory subscription
A29: B7 | B29: Annual recurring revenue (INR Cr) | C29: =C27*C28/100 -> 1.72 | D29: =D27*D28/100 -> 22.925 | E29: =E27*E28/100 -> 143.25
B31: THE CONTRADICTION THIS SHEET EXISTS TO SURFACE
B32: Base ACV assumed for a producer (INR lakh/yr) | C32: =D18 -> 50
B33: Break-even licence for the largest plausible tenant | C33: =Break_Even_Licence_Lakh -> 28.1 | F33: From Scenario E: above this, that customer is cheaper commissioning bespoke.
B34: Gap | C34: =C32-C33 -> 21.9 | D34: INR lakh/yr | F34: Positive means the assumed price exceeds what the biggest customer can justify.
B36: Reading it honestly | C36: The producer market is listable but small, and the base annual contract value assumed here exceeds the break-even for the largest plausible tenant. Either the price is too high, or the largest government producers are not the segment the product is for. Two conversations with accredited producers would settle it, and would also replace the addressable share in both models — the weakest input in this entire workbook, and the one that moves the answer most.

Sheet Product Sensitivity
A1: Product Build — What Moves the Number
A2: Same treatment the IPC estimate gets. Each row is a re-run of the simulation, not a multiplier.
A4: Rank | B4: Variable | C4: Range tested | D4: P80 low (PD) | E4: P80 high (PD) | F4: Swing (PD) | G4: Reading
A5: 1 | B5: Overall estimate accuracy | C5: every module ±30% | D5: 1251 | E5: 2101 | F5: =E5-D5 -> 850 | G5: Dominates: the estimate's own accuracy, not any single decision.
A6: 2 | B6: Exogenous risks realised | C6: none fire vs all fire | D6: 1439 | E6: 1825 | F6: =E6-D6 -> 386
A7: 3 | B7: Multi-tenancy depth | C7: row isolation vs per-tenant keys | D7: 1620 | E7: 1795 | F7: =E7-D7 -> 175
A8: 4 | B8: Certificate templating | C8: one format vs a designer | D8: 1635 | E8: 1770 | F8: =E8-D8 -> 135
A9: 5 | B9: Correlation between modules | C9: independent vs strongly coupled | D9: 1639 | E9: 1731 | F9: =E9-D9 -> 92
A10: 6 | B10: Field applications | C10: dropped vs both shipped | D10: 1613 | E10: 1705 | F10: =E10-D10 -> 92
B12: P80 baseline for comparison | D12: 1675

Sheet Product Funding
A1: Product Build — Funding, Ramp and Cross-check
A2: The IPC number is defended six ways. This gives the product number the same treatment.
B4: MONTHLY PROFILE — 12-month build at P80
A5: Ref | B5: Line | C5: M1 | D5: M2 | E5: M3 | F5: M4 | G5: M5 | H5: M6 | I5: Note
A6: C1 | B6: Ramp weight (relative) | C6: 0.4 | D6: 0.7 | E6: 1 | F6: 1.15 | G6: 1.25 | H6: 1.25 | I6: Peaks mid-build, tapers into hardening.
A7: C2 | B7: Person-days | C7: =ROUND(1675*C6/11.2,0) -> 60 | D7: =ROUND(1675*D6/11.2,0) -> 105 | E7: =ROUND(1675*E6/11.2,0) -> 150 | F7: =ROUND(1675*F6/11.2,0) -> 172 | G7: =ROUND(1675*G6/11.2,0) -> 187 | H7: =ROUND(1675*H6/11.2,0) -> 187
A8: C3 | B8: FTE | C8: =ROUND(C7/21,1) -> 2.9 | D8: =ROUND(D7/21,1) -> 5 | E8: =ROUND(E7/21,1) -> 7.1 | F8: =ROUND(F7/21,1) -> 8.2 | G8: =ROUND(G7/21,1) -> 8.9 | H8: =ROUND(H7/21,1) -> 8.9
A9: C4 | B9: Spend (INR lakh) | C9: =ROUND(C7*'Team & Rate Card'!$E$16/100000,1) -> 9.1 | D9: =ROUND(D7*'Team & Rate Card'!$E$16/100000,1) -> 15.9 | E9: =ROUND(E7*'Team & Rate Card'!$E$16/100000,1) -> 22.7 | F9: =ROUND(F7*'Team & Rate Card'!$E$16/100000,1) -> 26 | G9: =ROUND(G7*'Team & Rate Card'!$E$16/100000,1) -> 28.3 | H9: =ROUND(H7*'Team & Rate Card'!$E$16/100000,1) -> 28.3
B11: Peak FTE | C11: =MAX(C8:H8) -> 8.9 | I11: First six months shown; the profile is symmetric thereafter.
B12: Total build cost (INR Cr) | C12: =ROUND(1675*'Team & Rate Card'!$E$16/10000000,2) -> 2.53
B13: Peak funding required before first revenue (INR Cr) | C13: =C12 -> 2.53 | I13: No customer revenue during the build, so peak funding equals the whole build. That is the number to raise or absorb.
B15: INDEPENDENT CROSS-CHECK — screen and entity count
A16: Ref | B16: Artefact | C16: Count | D16: PD each | E16: Total (PD) | I16: Basis
A17: X1 | B17: Application screens | C17: 37 | D17: 14 | E17: =C17*D17 -> 518 | I17: Design, build, test, accessibility per screen
A18: X2 | B18: Domain entities with full lifecycle | C18: 22 | D18: 12 | E18: =C18*D18 -> 264 | I18: Schema, validation, state machine, audit
A19: X3 | B19: Integration surfaces | C19: 9 | D19: 22 | E19: =C19*D19 -> 198 | I19: LIMS, ERP, courier, payment, identity, e-invoicing
A20: X4 | B20: Statistical routines | C20: 6 | D20: 18 | E20: =C20*D20 -> 108 | I20: ANOVA, regression, consensus, budget, tornado, holder list
A21: X5 | B21: Compliance artefacts | C21: 8 | D21: 26 | E21: =C21*D21 -> 208 | I21: Clause map, validation pack, retention, residency
B22: Cross-check total (PD) | E22: =SUM(E17:E21) -> 1296
B23: Bottom-up P80 (PD) | E23: 1675
B24: Divergence | E24: =(E22-1675)/1675 -> -0.22626866 | I24: Two methods built from different primitives. A divergence under about 20% is agreement; beyond that, reconcile before committing.

Sheet Effort - Mobile & IPRS
A1: Workstream A-G | Mobile App for IPRS/IMPRS + Admin Console
A2: Pink = scope the document omits. Green = scope found only by inspecting the live estate. Sigma = (Pess - Opt) / 6.
A4: Ref | B4: Workstream / Module | C4: Source | D4: Opt (PD) | E4: Likely (PD) | F4: Pess (PD) | G4: Expected (PD) | H4: Sigma (PD) | I4: Notes
A5: A | B5: Discovery & Architecture
A6: A1 | B6: Requirements elaboration, SRS and traceability matrix | C6: Doc A | D6: 22 | E6: 32 | F6: 50 | G6: =ROUND((D6+4*E6+F6)/6,0) -> 33 | H6: =ROUND((F6-D6)/6,1) -> 4.7 | I6: 39 obligations, no acceptance criteria.
A7: A2 | B7: Solution architecture, domain model, integration contracts | C7: Doc A | D7: 18 | E7: 28 | F7: 45 | G7: =ROUND((D7+4*E7+F7)/6,0) -> 29 | H7: =ROUND((F7-D7)/6,1) -> 4.5 | I7: Must resolve catalogue ownership against the OpenCart estate.
B8: A subtotal | D8: =SUM(D6:D7) -> 40 | E8: =SUM(E6:E7) -> 60 | F8: =SUM(F6:F7) -> 95 | G8: =SUM(G6:G7) -> 62 | H8: =ROUND(SQRT(SUMPRODUCT(H6:H7,H6:H7)),1) -> 6.5
A10: B | B10: Experience Design
A11: B1 | B11: Design system and accessible mobile UI kit | C11: Doc A §7 | D11: 18 | E11: 26 | F11: 40 | G11: =ROUND((D11+4*E11+F11)/6,0) -> 27 | H11: =ROUND((F11-D11)/6,1) -> 3.7 | I11: WCAG 2.1 AA assumed; Doc A omits the level.
A12: B2 | B12: Mobile screen design, ~55 screens, two platforms | C12: Doc A | D12: 24 | E12: 36 | F12: 52 | G12: =ROUND((D12+4*E12+F12)/6,0) -> 37 | H12: =ROUND((F12-D12)/6,1) -> 4.7
A13: B3 | B13: Admin console design, ~40 screens, four roles | C13: Doc A §6 | D13: 18 | E13: 28 | F13: 42 | G13: =ROUND((D13+4*E13+F13)/6,0) -> 29 | H13: =ROUND((F13-D13)/6,1) -> 4
B14: B subtotal | D14: =SUM(D11:D13) -> 60 | E14: =SUM(E11:E13) -> 90 | F14: =SUM(F11:F13) -> 134 | G14: =SUM(G11:G13) -> 93 | H14: =ROUND(SQRT(SUMPRODUCT(H11:H13,H11:H13)),1) -> 7.2
A16: C | B16: Mobile Application (iOS + Android)
A17: C1 | B17: App foundation, navigation, state, mobile CI/CD | C17: Doc A | D17: 24 | E17: 34 | F17: 50 | G17: =ROUND((D17+4*E17+F17)/6,0) -> 35 | H17: =ROUND((F17-D17)/6,1) -> 4.3
A18: C2 | B18: Registration, OTP, biometric, MFA, institutional onboarding | C18: Doc A §1 | D18: 20 | E18: 30 | F18: 45 | G18: =ROUND((D18+4*E18+F18)/6,0) -> 31 | H18: =ROUND((F18-D18)/6,1) -> 4.2 | I18: GSTIN validation assumed in scope.
A19: C3 | B19: IPRS/IMPRS catalogue, lot detail, CoA / LVS / SDS viewer | C19: Doc A §2.1 | D19: 28 | E19: 40 | F19: 58 | G19: =ROUND((D19+4*E19+F19)/6,0) -> 41 | H19: =ROUND((F19-D19)/6,1) -> 5 | I19: Verified 1,341 priced SKUs across the two published lists.
A20: C4 | B20: Publications and subscriptions, edition history, renewals | C20: Doc A §2.2 | D20: 15 | E20: 22 | F20: 34 | G20: =ROUND((D20+4*E20+F20)/6,0) -> 23 | H20: =ROUND((F20-D20)/6,1) -> 3.2 | I20: Overlaps the portal catalogue — see Unification.
A21: C5 | B21: Smart search, filters, predictive, voice, recommendations | C21: Doc A §3.1 | D21: 20 | E21: 30 | F21: 46 | G21: =ROUND((D21+4*E21+F21)/6,0) -> 31 | H21: =ROUND((F21-D21)/6,1) -> 4.3
A22: C6 | B22: Cart, checkout and order lifecycle | C22: NOT IN DOC | D22: 30 | E22: 45 | F22: 68 | G22: =ROUND((D22+4*E22+F22)/6,0) -> 46 | H22: =ROUND((F22-D22)/6,1) -> 6.3 | I22: GAP: Doc A defines no ordering journey despite being a sales app.
A23: C7 | B23: Payment: gateway SDK, UPI, cards, netbanking, PO approval | C23: Doc A §4 | D23: 20 | E23: 30 | F23: 46 | G23: =ROUND((D23+4*E23+F23)/6,0) -> 31 | H23: =ROUND((F23-D23)/6,1) -> 4.3 | I23: PCI scope assumed SAQ-A via hosted fields.
A24: C8 | B24: Notifications: push, SMS, email, preference centre | C24: Doc A §5.1 | D24: 12 | E24: 18 | F24: 28 | G24: =ROUND((D24+4*E24+F24)/6,0) -> 19 | H24: =ROUND((F24-D24)/6,1) -> 2.7
A25: C9 | B25: Feedback, support ticketing, FAQ, self-help | C25: Doc A §5.3 | D25: 14 | E25: 20 | F25: 30 | G25: =ROUND((D25+4*E25+F25)/6,0) -> 21 | H25: =ROUND((F25-D25)/6,1) -> 2.7
A26: C10 | B26: Accessibility engineering to WCAG 2.1 AA, both platforms | C26: Doc A §7 | D26: 16 | E26: 25 | F26: 40 | G26: =ROUND((D26+4*E26+F26)/6,0) -> 26 | H26: =ROUND((F26-D26)/6,1) -> 4
A27: C11 | B27: GIGW 3.0 mobile conformance and CERT-In cyber chapter | C27: NOT IN DOC | D27: 14 | E27: 20 | F27: 32 | G27: =ROUND((D27+4*E27+F27)/6,0) -> 21 | H27: =ROUND((F27-D27)/6,1) -> 3 | I27: GAP: GIGW 3.0's cybersecurity chapter explicitly covers mobile apps. Doc A never cites GIGW.
A28: C12 | B28: App hardening: pinning, root detection, obfuscation, cache | C28: Doc A §7 | D28: 13 | E28: 20 | F28: 32 | G28: =ROUND((D28+4*E28+F28)/6,0) -> 21 | H28: =ROUND((F28-D28)/6,1) -> 3.2
A29: C13 | B29: Store submission, release engineering, phased rollout | C29: Doc A | D29: 8 | E29: 12 | F29: 20 | G29: =ROUND((D29+4*E29+F29)/6,0) -> 13 | H29: =ROUND((F29-D29)/6,1) -> 2 | I29: Doc A's simultaneous-release clause is not achievable through store review.
B30: C subtotal | D30: =SUM(D17:D29) -> 234 | E30: =SUM(E17:E29) -> 346 | F30: =SUM(F17:F29) -> 529 | G30: =SUM(G17:G29) -> 359 | H30: =ROUND(SQRT(SUMPRODUCT(H17:H29,H17:H29)),1) -> 14.2
A32: D | B32: Admin Console (web)
A33: D1 | B33: Console foundation, four-role RBAC, audit instrumentation | C33: Doc A §6 | D33: 24 | E33: 34 | F33: 50 | G33: =ROUND((D33+4*E33+F33)/6,0) -> 35 | H33: =ROUND((F33-D33)/6,1) -> 4.3
A34: D2 | B34: IPRS Admin: lots, batches, expiry, stock signals | C34: Doc A §6 | D34: 22 | E34: 32 | F34: 48 | G34: =ROUND((D34+4*E34+F34)/6,0) -> 33 | H34: =ROUND((F34-D34)/6,1) -> 4.3
A35: D3 | B35: CoA and Lot Validity Statement generation engine | C35: Doc A §2.1 | D35: 16 | E35: 24 | F35: 38 | G35: =ROUND((D35+4*E35+F35)/6,0) -> 25 | H35: =ROUND((F35-D35)/6,1) -> 3.7
A36: D4 | B36: Price-tier engine and government-organisation assignment | C36: Doc A §4 | D36: 16 | E36: 24 | F36: 38 | G36: =ROUND((D36+4*E36+F36)/6,0) -> 25 | H36: =ROUND((F36-D36)/6,1) -> 3.7 | I36: REDUCED from v1: IPC already publishes a two-tier price list at exactly 50%. This is tier assignment, not a discount engine.
A37: D5 | B37: Verification workflow: document review, approval, revalidation | C37: Doc A §4 | D37: 18 | E37: 26 | F37: 40 | G37: =ROUND((D37+4*E37+F37)/6,0) -> 27 | H37: =ROUND((F37-D37)/6,1) -> 3.7 | I37: This, not the arithmetic, is the real control.
A38: D6 | B38: Dispatch Admin: scheduling, couriers, slips, tracking | C38: Doc A §6 | D38: 27 | E38: 40 | F38: 60 | G38: =ROUND((D38+4*E38+F38)/6,0) -> 41 | H38: =ROUND((F38-D38)/6,1) -> 5.5 | I38: Cold-chain handling absent from Doc A — risk K11.
A39: D7 | B39: Order management console, refunds, cancellations | C39: Doc A §4 | D39: 17 | E39: 25 | F39: 38 | G39: =ROUND((D39+4*E39+F39)/6,0) -> 26 | H39: =ROUND((F39-D39)/6,1) -> 3.5
A40: D8 | B40: User management and registration logs | C40: Doc A §1 | D40: 10 | E40: 15 | F40: 24 | G40: =ROUND((D40+4*E40+F40)/6,0) -> 16 | H40: =ROUND((F40-D40)/6,1) -> 2.3
A41: D9 | B41: Notification console: templates, scheduling, delivery reports | C41: Doc A §5.2 | D41: 13 | E41: 20 | F41: 30 | G41: =ROUND((D41+4*E41+F41)/6,0) -> 21 | H41: =ROUND((F41-D41)/6,1) -> 2.8
A42: D10 | B42: Feedback and ticket management, escalation | C42: Doc A §5.4 | D42: 13 | E42: 20 | F42: 30 | G42: =ROUND((D42+4*E42+F42)/6,0) -> 21 | H42: =ROUND((F42-D42)/6,1) -> 2.8
A43: D11 | B43: Search analytics and demand reporting | C43: Doc A §3.2 | D43: 15 | E43: 22 | F43: 34 | G43: =ROUND((D43+4*E43+F43)/6,0) -> 23 | H43: =ROUND((F43-D43)/6,1) -> 3.2
A44: D12 | B44: Reporting engine, role-scoped, PDF/Excel, scheduling | C44: Doc A §6 | D44: 24 | E44: 35 | F44: 52 | G44: =ROUND((D44+4*E44+F44)/6,0) -> 36 | H44: =ROUND((F44-D44)/6,1) -> 4.7
...

Sheet Effort - Website
A1: Workstream H-S | Website Redesign, Replatform and Migration
A2: Pink = scope the document omits. Green = scope found only by inspecting the live estate. Sigma = (Pess - Opt) / 6.
A4: Ref | B4: Workstream / Module | C4: Source | D4: Opt (PD) | E4: Likely (PD) | F4: Pess (PD) | G4: Expected (PD) | H4: Sigma (PD) | I4: Notes
A5: H | B5: Discovery & Content Strategy
A6: H1 | B6: Discovery, workshops, information architecture, sitemap | C6: Doc B §1.1 | D6: 18 | E6: 28 | F6: 44 | G6: =ROUND((D6+4*E6+F6)/6,0) -> 29 | H6: =ROUND((F6-D6)/6,1) -> 4.3
A7: H2 | B7: Content audit and migration plan | C7: NOT IN DOC | D7: 8 | E7: 13 | F7: 22 | G7: =ROUND((D7+4*E7+F7)/6,0) -> 14 | H7: =ROUND((F7-D7)/6,1) -> 2.3 | I7: GAP, but now scoped from the live estate rather than assumed.
B8: H subtotal | D8: =SUM(D6:D7) -> 26 | E8: =SUM(E6:E7) -> 41 | F8: =SUM(F6:F7) -> 66 | G8: =SUM(G6:G7) -> 43 | H8: =ROUND(SQRT(SUMPRODUCT(H6:H7,H6:H7)),1) -> 4.9
A10: I | B10: Experience Design
A11: I1 | B11: GIGW 3.0 / DBIM design system, bilingual type and grid | C11: Doc B §1.1 | D11: 20 | E11: 30 | F11: 46 | G11: =ROUND((D11+4*E11+F11)/6,0) -> 31 | H11: =ROUND((F11-D11)/6,1) -> 4.3 | I11: 88 mandatory GIGW guidelines across four domains.
A12: I2 | B12: Template design, ~28 page templates | C12: Doc B §1.3 | D12: 28 | E12: 42 | F12: 62 | G12: =ROUND((D12+4*E12+F12)/6,0) -> 43 | H12: =ROUND((F12-D12)/6,1) -> 5.7
A13: I3 | B13: Commerce and account journey design | C13: Doc B §1.7 | D13: 10 | E13: 16 | F13: 26 | G13: =ROUND((D13+4*E13+F13)/6,0) -> 17 | H13: =ROUND((F13-D13)/6,1) -> 2.7
B14: I subtotal | D14: =SUM(D11:D13) -> 58 | E14: =SUM(E11:E13) -> 88 | F14: =SUM(F11:F13) -> 134 | G14: =SUM(G11:G13) -> 91 | H14: =ROUND(SQRT(SUMPRODUCT(H11:H13,H11:H13)),1) -> 7.6
A16: J | B16: CMS Platform
A17: J1 | B17: CMS platform setup, hardening, environments | C17: Doc B §1.2 | D17: 16 | E17: 24 | F17: 38 | G17: =ROUND((D17+4*E17+F17)/6,0) -> 25 | H17: =ROUND((F17-D17)/6,1) -> 3.7 | I17: Replaces Joomla.
A18: J2 | B18: RBAC and editorial approval workflow | C18: Doc B §1.2.1 | D18: 14 | E18: 20 | F18: 32 | G18: =ROUND((D18+4*E18+F18)/6,0) -> 21 | H18: =ROUND((F18-D18)/6,1) -> 3
A19: J3 | B19: Bilingual WYSIWYG authoring, spellcheck, media embed | C19: Doc B §1.2.1 | D19: 8 | E19: 12 | F19: 20 | G19: =ROUND((D19+4*E19+F19)/6,0) -> 13 | H19: =ROUND((F19-D19)/6,1) -> 2
A20: J4 | B20: Scheduling, auto-publish, auto-expire, expiry alerts | C20: Doc B §1.2.1 | D20: 7 | E20: 10 | F20: 16 | G20: =ROUND((D20+4*E20+F20)/6,0) -> 11 | H20: =ROUND((F20-D20)/6,1) -> 1.5
A21: J5 | B21: Backup, versioning, rollback, version compare | C21: Doc B §1.2.1 | D21: 8 | E21: 12 | F21: 20 | G21: =ROUND((D21+4*E21+F21)/6,0) -> 13 | H21: =ROUND((F21-D21)/6,1) -> 2
A22: J6 | B22: Immutable CMS audit trail and exportable logs | C22: Doc B §1.2.1 | D22: 12 | E22: 18 | F22: 28 | G22: =ROUND((D22+4*E22+F22)/6,0) -> 19 | H22: =ROUND((F22-D22)/6,1) -> 2.7
A23: J7 | B23: Archival engine: rules, retention, archive section, labelling | C23: Doc B §1.2.4 | D23: 14 | E23: 20 | F23: 32 | G23: =ROUND((D23+4*E23+F23)/6,0) -> 21 | H23: =ROUND((F23-D23)/6,1) -> 3 | I23: Live estate shows a 2023 G20 banner and a 2019 site map — the requirement is well founded.
B24: J subtotal | D24: =SUM(D17:D23) -> 79 | E24: =SUM(E17:E23) -> 116 | F24: =SUM(F17:F23) -> 186 | G24: =SUM(G17:G23) -> 123 | H24: =ROUND(SQRT(SUMPRODUCT(H17:H23,H17:H23)),1) -> 7
A26: K | B26: Content, Multimedia & Facilities
A27: K1 | B27: Video platform integration, player, captions, transcripts | C27: Doc B §1.2.2 | D27: 18 | E27: 28 | F27: 44 | G27: =ROUND((D27+4*E27+F27)/6,0) -> 29 | H27: =ROUND((F27-D27)/6,1) -> 4.3
A28: K2 | B28: Image wizard: gallery, resize, alt text, bulk upload | C28: Doc B §1.2.2 | D28: 10 | E28: 16 | F28: 26 | G28: =ROUND((D28+4*E28+F28)/6,0) -> 17 | H28: =ROUND((F28-D28)/6,1) -> 2.7
A29: K3 | B29: Document management: versioning, indexing, secure download | C29: Doc B §1.2.3 | D29: 16 | E29: 24 | F29: 38 | G29: =ROUND((D29+4*E29+F29)/6,0) -> 25 | H29: =ROUND((F29-D29)/6,1) -> 3.7
A30: K4 | B30: Event calendar, registration, reminders, archive | C30: Doc B §1.2.3 | D30: 20 | E30: 30 | F30: 46 | G30: =ROUND((D30+4*E30+F30)/6,0) -> 31 | H30: =ROUND((F30-D30)/6,1) -> 4.3
A31: K5 | B31: FAQ and glossary modules | C31: Doc B §1.2.3 | D31: 12 | E31: 18 | F31: 28 | G31: =ROUND((D31+4*E31+F31)/6,0) -> 19 | H31: =ROUND((F31-D31)/6,1) -> 2.7
A32: K6 | B32: Polls and visitor survey with analytics | C32: Doc B §1.2.3 | D32: 10 | E32: 16 | F32: 26 | G32: =ROUND((D32+4*E32+F32)/6,0) -> 17 | H32: =ROUND((F32-D32)/6,1) -> 2.7
A33: K7 | B33: Public forum: threads, moderation, reputation, redressal | C33: Doc B §1.2.3 | D33: 30 | E33: 45 | F33: 68 | G33: =ROUND((D33+4*E33+F33)/6,0) -> 46 | H33: =ROUND((F33-D33)/6,1) -> 6.3 | I33: Largest CMS module; heaviest moderation risk.
A34: K8 | B34: Recruitment form, tracking, export, HR dashboard | C34: Doc B §1.2.3 | D34: 16 | E34: 24 | F34: 38 | G34: =ROUND((D34+4*E34+F34)/6,0) -> 25 | H34: =ROUND((F34-D34)/6,1) -> 3.7
B35: K subtotal | D35: =SUM(D27:D34) -> 132 | E35: =SUM(E27:E34) -> 201 | F35: =SUM(F27:F34) -> 314 | G35: =SUM(G27:G34) -> 209 | H35: =ROUND(SQRT(SUMPRODUCT(H27:H34,H27:H34)),1) -> 11.2
A37: L | B37: Frontend & Engagement
A38: L1 | B38: Templates, mega menu, breadcrumbs, sticky nav, cards | C38: Doc B §1.3.1 | D38: 34 | E38: 50 | F38: 74 | G38: =ROUND((D38+4*E38+F38)/6,0) -> 51 | H38: =ROUND((F38-D38)/6,1) -> 6.7
A39: L2 | B39: Personalisation widgets, quick tiles, one-click downloads | C39: Doc B §1.3.3 | D39: 12 | E39: 18 | F39: 28 | G39: =ROUND((D39+4*E39+F39)/6,0) -> 19 | H39: =ROUND((F39-D39)/6,1) -> 2.7
A40: L3 | B40: Bilingual framework and language toggle | C40: Doc B §1.1 | D40: 10 | E40: 15 | F40: 26 | G40: =ROUND((D40+4*E40+F40)/6,0) -> 16 | H40: =ROUND((F40-D40)/6,1) -> 2.7 | I40: REDUCED from v1: a Hindi site already exists at /hi/.
A41: L4 | B41: Accessibility engineering to WCAG 2.1 AA | C41: Doc B §1.1 | D41: 26 | E41: 38 | F41: 58 | G41: =ROUND((D41+4*E41+F41)/6,0) -> 39 | H41: =ROUND((F41-D41)/6,1) -> 5.3
B42: L subtotal | D42: =SUM(D38:D41) -> 82 | E42: =SUM(E38:E41) -> 121 | F42: =SUM(F38:F41) -> 186 | G42: =SUM(G38:G41) -> 125 | H42: =ROUND(SQRT(SUMPRODUCT(H38:H41,H38:H41)),1) -> 9.4
A44: M | B44: Search & AI Layer
A45: M1 | B45: Search platform, indexing, multilingual facets, relevance | C45: Doc B §1.3.2 | D45: 22 | E45: 32 | F45: 50 | G45: =ROUND((D45+4*E45+F45)/6,0) -> 33 | H45: =ROUND((F45-D45)/6,1) -> 4.7
A46: M2 | B46: Semantic / vector search and recommendations | C46: Doc B §1.1 | D46: 18 | E46: 28 | F46: 44 | G46: =ROUND((D46+4*E46+F46)/6,0) -> 29 | H46: =ROUND((F46-D46)/6,1) -> 4.3
...

Sheet Monte Carlo
A1: Confidence — Monte Carlo Simulation
A2: 100,000 iterations. Beta-PERT marginals on every module, correlated through a Gaussian copula, with exogenous risk events sampled inside the same run. Replaces the v2 P80-plus-EMV method.
B4: WHY THIS REPLACES THE v2 METHOD
B5: Composition error | C5: v2 added an expected value to a P80 and labelled the sum a P80. A mean plus a percentile is neither. On this distribution the v2 figure of 3,623 PD actually sits at about P81.
B6: Distribution shape | C6: v2 implied a normal spread. Task durations are bounded below and right-skewed; a normal understates the upper tail and permits negative durations. This run uses Beta-PERT, derived from the same optimistic / likely / pessimistic values already in the model.
B7: Correlation | C7: v2 multiplied sigma by 3.5, a factor chosen by hand. Here correlation is an explicit parameter with its effect shown across four values, so the assumption is visible and testable rather than buried.
B8: Double counting | C8: v2's register charged 135 PD of expected value for requirement volatility — which is exactly what the optimistic-to-pessimistic spread on all 122 modules already encodes. It is removed, and six further risks are reduced to their marginal exposure beyond the module pessimistic.
B9: Savings realisation | C9: v2 treated the unification saving as certain. Here it is sampled at 70 to 110 per cent of nominal, since savings under-deliver more often than they over-deliver.
B11: SIMULATION PARAMETERS
B12: Iterations | C12: 100,000
B13: Modules sampled | C13: 122
B14: Marginal distribution | C14: Beta-PERT from O / M / P
B15: Dependence | C15: Gaussian copula, single common factor
B16: Correlation used for headline | C16: 0.5
B17: Exogenous risk events | C17: 13
B18: Endogenous risks removed | C18: K10 (requirement volatility)
B19: Unification saving | C19: 524 PD, now computed from source modules, sampled 70–110%
B20: Random seed | C20: 20260818 (reproducible)
B22: SENSITIVITY TO THE CORRELATION ASSUMPTION
B23: Correlation | C23: P50 (PD) | D23: P70 (PD) | E23: P80 (PD) | F23: P90 (PD) | G23: P95 (PD) | H23: Reading
B24: rho = 0.0 | C24: 3446 | D24: 3574 | E24: 3619 | F24: 3670 | G24: 3708 | H24: Independent modules. Unrealistic — one team, one client, one set of ambiguities.
B25: rho = 0.3 | C25: 3431 | D25: 3572 | E25: 3652 | F25: 3756 | G25: 3838 | H25: Weak common cause. Plausible for a portfolio of unrelated projects.
B26: rho = 0.5 | C26: 3424 | D26: 3605 | E26: 3714 | F26: 3861 | G26: 3984 | H26: RECOMMENDED. Single accountable team on a single programme with shared requirement risk.
B27: rho = 0.7 | C27: 3417 | D27: 3654 | E27: 3797 | F27: 3994 | G27: 4154 | H27: Strong common cause. Appropriate if requirements remain unfrozen at award.
B29: RECOMMENDED BASIS
B30: P50 — even odds | C30: 3424 | D30: person-days | H30: Half of comparable programmes finish inside this. Never bid it.
B31: P80 — RECOMMENDED BID BASIS | C31: 3714 | D31: person-days | H31: Standard commercial basis for a fixed-price government contract.
B32: P90 — conservative | C32: 3861 | D32: person-days | H32: Use where liquidated damages bite hard or the schedule cannot move.
B33: P80 with K1 resolved pre-award | C33: 3500 | D33: person-days | H33: Asking one clarification question before pricing is worth 216 PD.
B35: Change against the v3 figure of 3,608 PD | C35: 106 | H35: Moved because the unification saving is no longer 635 PD hardcoded. Computed from the modules it actually reduces, it is 524 PD — so the earlier figure over-claimed the saving and understated the effort.
B37: DISTRIBUTION (rho = 0.5)
B38: Bucket midpoint (PD) | C38: Iterations (count)
B39: 2092 | C39: 5
B40: 2183 | C40: 5
B41: 2274 | C41: 48
B42: 2365 | C42: 155
B43: 2456 | C43: 350
B44: 2547 | C44: 786
B45: 2638 | C45: 1501
B46: 2729 | C46: 2590
...

Sheet Scenario C Model
A1: Scenario C — Phase 1 Release, Modelled
A2: Replaces the 0.62x multiplier. Each build module is tagged to a phase; QA and programme management scale with the phase-1 build share.
A4: Ref | B4: Module | C4: Expected (PD) | D4: Phase | E4: In phase 1 (PD) | F4: Rationale where deferred
A5: A1 | B5: Requirements elaboration, SRS and traceability matrix | C5: ='Effort - Mobile & IPRS'!G6 -> 33 | D5: Phase 1 | E5: =IF(D5="Phase 1",C5,0) -> 33
A6: A2 | B6: Solution architecture, domain model, integration contracts | C6: ='Effort - Mobile & IPRS'!G7 -> 29 | D6: Phase 1 | E6: =IF(D6="Phase 1",C6,0) -> 29
A7: B1 | B7: Design system and accessible mobile UI kit | C7: ='Effort - Mobile & IPRS'!G11 -> 27 | D7: Phase 1 | E7: =IF(D7="Phase 1",C7,0) -> 27
A8: B2 | B8: Mobile screen design, ~55 screens, two platforms | C8: ='Effort - Mobile & IPRS'!G12 -> 37 | D8: Phase 2 | E8: =IF(D8="Phase 1",C8,0) -> 0 | F8: Mobile design deferred with the app.
A9: B3 | B9: Admin console design, ~40 screens, four roles | C9: ='Effort - Mobile & IPRS'!G13 -> 29 | D9: Phase 1 | E9: =IF(D9="Phase 1",C9,0) -> 29
A10: C1 | B10: App foundation, navigation, state, mobile CI/CD | C10: ='Effort - Mobile & IPRS'!G17 -> 35 | D10: Phase 2 | E10: =IF(D10="Phase 1",C10,0) -> 0 | F10: Mobile app deferred; the portal carries commerce in phase 1.
A11: C2 | B11: Registration, OTP, biometric, MFA, institutional onboarding | C11: ='Effort - Mobile & IPRS'!G18 -> 31 | D11: Phase 2 | E11: =IF(D11="Phase 1",C11,0) -> 0 | F11: Mobile app deferred; the portal carries commerce in phase 1.
A12: C3 | B12: IPRS/IMPRS catalogue, lot detail, CoA / LVS / SDS viewer | C12: ='Effort - Mobile & IPRS'!G19 -> 41 | D12: Phase 2 | E12: =IF(D12="Phase 1",C12,0) -> 0 | F12: Mobile app deferred; the portal carries commerce in phase 1.
A13: C4 | B13: Publications and subscriptions, edition history, renewals | C13: ='Effort - Mobile & IPRS'!G20 -> 23 | D13: Phase 2 | E13: =IF(D13="Phase 1",C13,0) -> 0 | F13: Mobile app deferred; the portal carries commerce in phase 1.
A14: C5 | B14: Smart search, filters, predictive, voice, recommendations | C14: ='Effort - Mobile & IPRS'!G21 -> 31 | D14: Phase 2 | E14: =IF(D14="Phase 1",C14,0) -> 0 | F14: Mobile app deferred; the portal carries commerce in phase 1.
A15: C6 | B15: Cart, checkout and order lifecycle | C15: ='Effort - Mobile & IPRS'!G22 -> 46 | D15: Phase 2 | E15: =IF(D15="Phase 1",C15,0) -> 0 | F15: Mobile app deferred; the portal carries commerce in phase 1.
A16: C7 | B16: Payment: gateway SDK, UPI, cards, netbanking, PO approval | C16: ='Effort - Mobile & IPRS'!G23 -> 31 | D16: Phase 2 | E16: =IF(D16="Phase 1",C16,0) -> 0 | F16: Mobile app deferred; the portal carries commerce in phase 1.
A17: C8 | B17: Notifications: push, SMS, email, preference centre | C17: ='Effort - Mobile & IPRS'!G24 -> 19 | D17: Phase 2 | E17: =IF(D17="Phase 1",C17,0) -> 0 | F17: Mobile app deferred; the portal carries commerce in phase 1.
A18: C9 | B18: Feedback, support ticketing, FAQ, self-help | C18: ='Effort - Mobile & IPRS'!G25 -> 21 | D18: Phase 2 | E18: =IF(D18="Phase 1",C18,0) -> 0 | F18: Mobile app deferred; the portal carries commerce in phase 1.
A19: C10 | B19: Accessibility engineering to WCAG 2.1 AA, both platforms | C19: ='Effort - Mobile & IPRS'!G26 -> 26 | D19: Phase 2 | E19: =IF(D19="Phase 1",C19,0) -> 0 | F19: Mobile app deferred; the portal carries commerce in phase 1.
A20: C11 | B20: GIGW 3.0 mobile conformance and CERT-In cyber chapter | C20: ='Effort - Mobile & IPRS'!G27 -> 21 | D20: Phase 2 | E20: =IF(D20="Phase 1",C20,0) -> 0 | F20: Mobile app deferred; the portal carries commerce in phase 1.
A21: C12 | B21: App hardening: pinning, root detection, obfuscation, cache | C21: ='Effort - Mobile & IPRS'!G28 -> 21 | D21: Phase 2 | E21: =IF(D21="Phase 1",C21,0) -> 0 | F21: Mobile app deferred; the portal carries commerce in phase 1.
A22: C13 | B22: Store submission, release engineering, phased rollout | C22: ='Effort - Mobile & IPRS'!G29 -> 13 | D22: Phase 2 | E22: =IF(D22="Phase 1",C22,0) -> 0 | F22: Mobile app deferred; the portal carries commerce in phase 1.
A23: D1 | B23: Console foundation, four-role RBAC, audit instrumentation | C23: ='Effort - Mobile & IPRS'!G33 -> 35 | D23: Phase 1 | E23: =IF(D23="Phase 1",C23,0) -> 35
A24: D2 | B24: IPRS Admin: lots, batches, expiry, stock signals | C24: ='Effort - Mobile & IPRS'!G34 -> 33 | D24: Phase 1 | E24: =IF(D24="Phase 1",C24,0) -> 33
A25: D3 | B25: CoA and Lot Validity Statement generation engine | C25: ='Effort - Mobile & IPRS'!G35 -> 25 | D25: Phase 1 | E25: =IF(D25="Phase 1",C25,0) -> 25
A26: D4 | B26: Price-tier engine and government-organisation assignment | C26: ='Effort - Mobile & IPRS'!G36 -> 25 | D26: Phase 1 | E26: =IF(D26="Phase 1",C26,0) -> 25
A27: D5 | B27: Verification workflow: document review, approval, revalidation | C27: ='Effort - Mobile & IPRS'!G37 -> 27 | D27: Phase 1 | E27: =IF(D27="Phase 1",C27,0) -> 27
A28: D6 | B28: Dispatch Admin: scheduling, couriers, slips, tracking | C28: ='Effort - Mobile & IPRS'!G38 -> 41 | D28: Phase 1 | E28: =IF(D28="Phase 1",C28,0) -> 41
A29: D7 | B29: Order management console, refunds, cancellations | C29: ='Effort - Mobile & IPRS'!G39 -> 26 | D29: Phase 1 | E29: =IF(D29="Phase 1",C29,0) -> 26
A30: D8 | B30: User management and registration logs | C30: ='Effort - Mobile & IPRS'!G40 -> 16 | D30: Phase 1 | E30: =IF(D30="Phase 1",C30,0) -> 16
A31: D9 | B31: Notification console: templates, scheduling, delivery reports | C31: ='Effort - Mobile & IPRS'!G41 -> 21 | D31: Phase 1 | E31: =IF(D31="Phase 1",C31,0) -> 21
A32: D10 | B32: Feedback and ticket management, escalation | C32: ='Effort - Mobile & IPRS'!G42 -> 21 | D32: Phase 1 | E32: =IF(D32="Phase 1",C32,0) -> 21
A33: D11 | B33: Search analytics and demand reporting | C33: ='Effort - Mobile & IPRS'!G43 -> 23 | D33: Phase 1 | E33: =IF(D33="Phase 1",C33,0) -> 23
A34: D12 | B34: Reporting engine, role-scoped, PDF/Excel, scheduling | C34: ='Effort - Mobile & IPRS'!G44 -> 36 | D34: Phase 1 | E34: =IF(D34="Phase 1",C34,0) -> 36
A35: D13 | B35: Immutable audit log: append-only, hash-chained, exportable | C35: ='Effort - Mobile & IPRS'!G45 -> 26 | D35: Phase 1 | E35: =IF(D35="Phase 1",C35,0) -> 26
A36: E1 | B36: API platform: catalogue, lot, order, identity services | C36: ='Effort - Mobile & IPRS'!G49 -> 72 | D36: Phase 1 | E36: =IF(D36="Phase 1",C36,0) -> 72
A37: E2 | B37: Document generation: CoA, LVS, GST invoice, dispatch slip | C37: ='Effort - Mobile & IPRS'!G50 -> 31 | D37: Phase 1 | E37: =IF(D37="Phase 1",C37,0) -> 31
A38: E3 | B38: Payment gateway and settlement reconciliation | C38: ='Effort - Mobile & IPRS'!G51 -> 13 | D38: Phase 1 | E38: =IF(D38="Phase 1",C38,0) -> 13
A39: E4 | B39: Courier API integration and tracking webhooks | C39: ='Effort - Mobile & IPRS'!G52 -> 16 | D39: Phase 1 | E39: =IF(D39="Phase 1",C39,0) -> 16
A40: E5 | B40: Tally / ERP posting, reconciliation, GST e-invoicing (IRN) | C40: ='Effort - Mobile & IPRS'!G53 -> 21 | D40: Phase 1 | E40: =IF(D40="Phase 1",C40,0) -> 21
A41: E6 | B41: Pin-code serviceability API | C41: ='Effort - Mobile & IPRS'!G54 -> 5 | D41: Phase 1 | E41: =IF(D41="Phase 1",C41,0) -> 5
...

Sheet Scenario D Model
A1: Scenario D — Replatform, Modelled
A2: Replaces the 0.58x multiplier. Every module carries a disposition factor: what fraction survives if the live Joomla and OpenCart estate is upgraded rather than replaced.
A4: Ref | B4: Module | C4: Expected (PD) | D4: Factor (0–1, dimensionless) | E4: Retained (PD) | F4: Why the factor is not 1.00
A5: A1 | B5: Requirements elaboration, SRS and traceability matrix | C5: ='Effort - Mobile & IPRS'!G6 -> 33 | D5: 1 | E5: =ROUND(C5*D5,0) -> 33
A6: A2 | B6: Solution architecture, domain model, integration contracts | C6: ='Effort - Mobile & IPRS'!G7 -> 29 | D6: 1 | E6: =ROUND(C6*D6,0) -> 29
A7: B1 | B7: Design system and accessible mobile UI kit | C7: ='Effort - Mobile & IPRS'!G11 -> 27 | D7: 1 | E7: =ROUND(C7*D7,0) -> 27
A8: B2 | B8: Mobile screen design, ~55 screens, two platforms | C8: ='Effort - Mobile & IPRS'!G12 -> 37 | D8: 1 | E8: =ROUND(C8*D8,0) -> 37
A9: B3 | B9: Admin console design, ~40 screens, four roles | C9: ='Effort - Mobile & IPRS'!G13 -> 29 | D9: 1 | E9: =ROUND(C9*D9,0) -> 29
A10: C1 | B10: App foundation, navigation, state, mobile CI/CD | C10: ='Effort - Mobile & IPRS'!G17 -> 35 | D10: 1 | E10: =ROUND(C10*D10,0) -> 35
A11: C2 | B11: Registration, OTP, biometric, MFA, institutional onboarding | C11: ='Effort - Mobile & IPRS'!G18 -> 31 | D11: 1 | E11: =ROUND(C11*D11,0) -> 31
A12: C3 | B12: IPRS/IMPRS catalogue, lot detail, CoA / LVS / SDS viewer | C12: ='Effort - Mobile & IPRS'!G19 -> 41 | D12: 1 | E12: =ROUND(C12*D12,0) -> 41
A13: C4 | B13: Publications and subscriptions, edition history, renewals | C13: ='Effort - Mobile & IPRS'!G20 -> 23 | D13: 1 | E13: =ROUND(C13*D13,0) -> 23
A14: C5 | B14: Smart search, filters, predictive, voice, recommendations | C14: ='Effort - Mobile & IPRS'!G21 -> 31 | D14: 1 | E14: =ROUND(C14*D14,0) -> 31
A15: C6 | B15: Cart, checkout and order lifecycle | C15: ='Effort - Mobile & IPRS'!G22 -> 46 | D15: 1 | E15: =ROUND(C15*D15,0) -> 46
A16: C7 | B16: Payment: gateway SDK, UPI, cards, netbanking, PO approval | C16: ='Effort - Mobile & IPRS'!G23 -> 31 | D16: 1 | E16: =ROUND(C16*D16,0) -> 31
A17: C8 | B17: Notifications: push, SMS, email, preference centre | C17: ='Effort - Mobile & IPRS'!G24 -> 19 | D17: 1 | E17: =ROUND(C17*D17,0) -> 19
A18: C9 | B18: Feedback, support ticketing, FAQ, self-help | C18: ='Effort - Mobile & IPRS'!G25 -> 21 | D18: 1 | E18: =ROUND(C18*D18,0) -> 21
A19: C10 | B19: Accessibility engineering to WCAG 2.1 AA, both platforms | C19: ='Effort - Mobile & IPRS'!G26 -> 26 | D19: 1 | E19: =ROUND(C19*D19,0) -> 26
A20: C11 | B20: GIGW 3.0 mobile conformance and CERT-In cyber chapter | C20: ='Effort - Mobile & IPRS'!G27 -> 21 | D20: 1 | E20: =ROUND(C20*D20,0) -> 21
A21: C12 | B21: App hardening: pinning, root detection, obfuscation, cache | C21: ='Effort - Mobile & IPRS'!G28 -> 21 | D21: 1 | E21: =ROUND(C21*D21,0) -> 21
A22: C13 | B22: Store submission, release engineering, phased rollout | C22: ='Effort - Mobile & IPRS'!G29 -> 13 | D22: 1 | E22: =ROUND(C22*D22,0) -> 13
A23: D1 | B23: Console foundation, four-role RBAC, audit instrumentation | C23: ='Effort - Mobile & IPRS'!G33 -> 35 | D23: 1 | E23: =ROUND(C23*D23,0) -> 35
A24: D2 | B24: IPRS Admin: lots, batches, expiry, stock signals | C24: ='Effort - Mobile & IPRS'!G34 -> 33 | D24: 1 | E24: =ROUND(C24*D24,0) -> 33
A25: D3 | B25: CoA and Lot Validity Statement generation engine | C25: ='Effort - Mobile & IPRS'!G35 -> 25 | D25: 1 | E25: =ROUND(C25*D25,0) -> 25
A26: D4 | B26: Price-tier engine and government-organisation assignment | C26: ='Effort - Mobile & IPRS'!G36 -> 25 | D26: 1 | E26: =ROUND(C26*D26,0) -> 25
A27: D5 | B27: Verification workflow: document review, approval, revalidation | C27: ='Effort - Mobile & IPRS'!G37 -> 27 | D27: 1 | E27: =ROUND(C27*D27,0) -> 27
A28: D6 | B28: Dispatch Admin: scheduling, couriers, slips, tracking | C28: ='Effort - Mobile & IPRS'!G38 -> 41 | D28: 1 | E28: =ROUND(C28*D28,0) -> 41
A29: D7 | B29: Order management console, refunds, cancellations | C29: ='Effort - Mobile & IPRS'!G39 -> 26 | D29: 1 | E29: =ROUND(C29*D29,0) -> 26
A30: D8 | B30: User management and registration logs | C30: ='Effort - Mobile & IPRS'!G40 -> 16 | D30: 1 | E30: =ROUND(C30*D30,0) -> 16
A31: D9 | B31: Notification console: templates, scheduling, delivery reports | C31: ='Effort - Mobile & IPRS'!G41 -> 21 | D31: 1 | E31: =ROUND(C31*D31,0) -> 21
A32: D10 | B32: Feedback and ticket management, escalation | C32: ='Effort - Mobile & IPRS'!G42 -> 21 | D32: 1 | E32: =ROUND(C32*D32,0) -> 21
A33: D11 | B33: Search analytics and demand reporting | C33: ='Effort - Mobile & IPRS'!G43 -> 23 | D33: 1 | E33: =ROUND(C33*D33,0) -> 23
A34: D12 | B34: Reporting engine, role-scoped, PDF/Excel, scheduling | C34: ='Effort - Mobile & IPRS'!G44 -> 36 | D34: 1 | E34: =ROUND(C34*D34,0) -> 36
A35: D13 | B35: Immutable audit log: append-only, hash-chained, exportable | C35: ='Effort - Mobile & IPRS'!G45 -> 26 | D35: 1 | E35: =ROUND(C35*D35,0) -> 26
A36: E1 | B36: API platform: catalogue, lot, order, identity services | C36: ='Effort - Mobile & IPRS'!G49 -> 72 | D36: 1 | E36: =ROUND(C36*D36,0) -> 72
A37: E2 | B37: Document generation: CoA, LVS, GST invoice, dispatch slip | C37: ='Effort - Mobile & IPRS'!G50 -> 31 | D37: 1 | E37: =ROUND(C37*D37,0) -> 31
A38: E3 | B38: Payment gateway and settlement reconciliation | C38: ='Effort - Mobile & IPRS'!G51 -> 13 | D38: 1 | E38: =ROUND(C38*D38,0) -> 13
A39: E4 | B39: Courier API integration and tracking webhooks | C39: ='Effort - Mobile & IPRS'!G52 -> 16 | D39: 1 | E39: =ROUND(C39*D39,0) -> 16
A40: E5 | B40: Tally / ERP posting, reconciliation, GST e-invoicing (IRN) | C40: ='Effort - Mobile & IPRS'!G53 -> 21 | D40: 1 | E40: =ROUND(C40*D40,0) -> 21
A41: E6 | B41: Pin-code serviceability API | C41: ='Effort - Mobile & IPRS'!G54 -> 5 | D41: 1 | E41: =ROUND(C41*D41,0) -> 5
...

Sheet Scenario E Model
A1: Scenario E — IPC Adopts the Product
A2: The scenario the workbook never had. Each IPC module carries a factor: what fraction survives once Lotmark supplies the core.
A4: Ref | B4: IPC module | C4: Expected (PD) | D4: Factor (0–1, dimensionless) | E4: Surviving (PD) | F4: What the product displaces
A5: A1 | B5: Requirements elaboration, SRS and traceability matrix | C5: ='Effort - Mobile & IPRS'!G6 -> 33 | D5: 1 | E5: =ROUND(C5*D5,0) -> 33
A6: A2 | B6: Solution architecture, domain model, integration contracts | C6: ='Effort - Mobile & IPRS'!G7 -> 29 | D6: 1 | E6: =ROUND(C6*D6,0) -> 29
A7: B1 | B7: Design system and accessible mobile UI kit | C7: ='Effort - Mobile & IPRS'!G11 -> 27 | D7: 1 | E7: =ROUND(C7*D7,0) -> 27
A8: B2 | B8: Mobile screen design, ~55 screens, two platforms | C8: ='Effort - Mobile & IPRS'!G12 -> 37 | D8: 1 | E8: =ROUND(C8*D8,0) -> 37
A9: B3 | B9: Admin console design, ~40 screens, four roles | C9: ='Effort - Mobile & IPRS'!G13 -> 29 | D9: 1 | E9: =ROUND(C9*D9,0) -> 29
A10: C1 | B10: App foundation, navigation, state, mobile CI/CD | C10: ='Effort - Mobile & IPRS'!G17 -> 35 | D10: 1 | E10: =ROUND(C10*D10,0) -> 35
A11: C2 | B11: Registration, OTP, biometric, MFA, institutional onboarding | C11: ='Effort - Mobile & IPRS'!G18 -> 31 | D11: 1 | E11: =ROUND(C11*D11,0) -> 31
A12: C3 | B12: IPRS/IMPRS catalogue, lot detail, CoA / LVS / SDS viewer | C12: ='Effort - Mobile & IPRS'!G19 -> 41 | D12: 0.3 | E12: =ROUND(C12*D12,0) -> 12 | F12: Partly supplied by the product.
A13: C4 | B13: Publications and subscriptions, edition history, renewals | C13: ='Effort - Mobile & IPRS'!G20 -> 23 | D13: 0.3 | E13: =ROUND(C13*D13,0) -> 7 | F13: Partly supplied by the product.
A14: C5 | B14: Smart search, filters, predictive, voice, recommendations | C14: ='Effort - Mobile & IPRS'!G21 -> 31 | D14: 1 | E14: =ROUND(C14*D14,0) -> 31
A15: C6 | B15: Cart, checkout and order lifecycle | C15: ='Effort - Mobile & IPRS'!G22 -> 46 | D15: 1 | E15: =ROUND(C15*D15,0) -> 46
